<?xml version="1.0" ?>
<!-- =================================================================================== -->
<!-- |    This document was autogenerated by xacro from tractor.urdf.xacro             | -->
<!-- |    EDITING THIS FILE BY HAND IS NOT RECOMMENDED                                 | -->
<!-- =================================================================================== -->
<robot name="tractor">
  <gazebo>
    <plugin filename="libgazebo_ros_control.so" name="gazebo_ros_controller_manager">
      <robotNamespace>/tractor</robotNamespace>
      <robotSimType>gazebo_ros_control/DefaultRobotHWSim</robotSimType>
      <legacyModeNS>true</legacyModeNS>
      <controlPeriod>0.004</controlPeriod>
    </plugin>
    <plugin filename="libgazebo_ros_p3d.so" name="gazebo_ros_p3d">
      <robotNamespace>/tractor</robotNamespace>
      <bodyName>base_link</bodyName>
      <topicName>ground_truth</topicName>
      <frameName>world</frameName>
      <xyzOffsets>0 0 0</xyzOffsets>
      <rpyOffsets>0 0 0</rpyOffsets>
      <gaussianNoise>0</gaussianNoise>
      <alwaysOn>true</alwaysOn>
      <updateRate>250.0</updateRate>
    </plugin>
  </gazebo>
  <material name="green">
    <color rgba="0 1 0 1.0"/>
  </material>
  <material name="grey">
    <color rgba="0.296875 0.296875 0.296875 1.0"/>
  </material>
  <material name="yellow">
    <color rgba="0.75 0.75 0 1.0"/>
  </material>
  <material name="blue">
    <color rgba="0.0390625 0.48828125 0.70703125 1.0"/>
  </material>
  <material name="black">
    <color rgba="0 0 0 1.0"/>
  </material>
  <link name="base_link">
    </link>
  <link name="chassis">
    <inertial>
      <origin rpy="0 0 0" xyz="-0.0045758 0.077937 0.20368"/>
      <mass value="2.0333"/>
      <inertia ixx="0.040785" ixy="-0.00045334" ixz="7.2074E-05" iyy="0.077439" iyz="3.0873E-05" izz="0.045595"/>
    </inertial>
    <visual>
      <origin rpy="0 0 0" xyz="0 0 0"/>
      <geometry>
        <mesh filename="package://tractor_description/meshes/chassis.STL"/>
      </geometry>
      <material name="green"/>
    </visual>
    <collision>
      <origin rpy="0 0 0" xyz="0 0 0"/>
      <geometry>
        <mesh filename="package://tractor_description/meshes/chassis.STL"/>
      </geometry>
    </collision>
  </link>
  <joint name="chassis_joint" type="fixed">
    <origin rpy="0 0 0" xyz="0 0.225 0"/>
    <parent link="base_link"/>
    <child link="chassis"/>
    <axis xyz="0 0 0"/>
  </joint>
  <link name="ponte1">
    <!-- <inertial>
        <origin xyz="-0.0486832445707459 -0.0157825528331647 0.47101385376825" rpy="0 0 0" />
        <mass value="0.600172688597701" />
        <inertia ixx="0.00226804513830582" ixy="6.12976942084316E-06" ixz="0.000279583144630229" iyy="0.00684292127016085" iyz="7.5882956045762E-05" izz="0.00651687323092023" />
      </inertial> -->
    <visual>
      <origin rpy="0 0 0" xyz="0 0 0"/>
      <geometry>
        <mesh filename="package://tractor_description/meshes/meshes1/ponte1.STL"/>
      </geometry>
      <material name="grey"/>
    </visual>
    <!-- <collision>
        <origin xyz="0 0 0" rpy="0 0 0" />
        <geometry>
          <mesh filename="package://tractor_description/meshes/meshes1/ponte1.STL" />
        </geometry>
      </collision> -->
  </link>
  <joint name="ponte1_joint" type="fixed">
    <origin rpy="0 0 0" xyz="0 0.225 0"/>
    <parent link="base_link"/>
    <child link="ponte1"/>
    <axis xyz="0 0 0"/>
  </joint>
  <link name="cingolo1">
    <inertial>
      <origin rpy="0 0 0" xyz="-0.0186478543961228 0.0173558435086227 0"/>
      <mass value="5.37116770201882"/>
      <inertia ixx="0.119835058050815" ixy="0.0195379499468078" ixz="4.85729027387283E-17" iyy="0.414599681845954" iyz="3.20551941809325E-17" izz="0.519305950869416"/>
    </inertial>
    <visual>
      <origin rpy="0 0 0" xyz="0 0 0"/>
      <geometry>
        <mesh filename="package://tractor_description/meshes/meshes1/cingolo1.STL"/>
      </geometry>
      <material name="grey"/>
    </visual>
    <collision>
      <origin rpy="0 0 0" xyz="0 0 0"/>
      <geometry>
        <mesh filename="package://tractor_description/meshes/meshes1/cingolo1.STL"/>
      </geometry>
    </collision>
  </link>
  <joint name="cingolo1_joint" type="fixed">
    <origin rpy="1.5707963267949 0 3.14" xyz="-0.094340414586262 -0.301388567 -0.100112309063136"/>
    <parent link="base_link"/>
    <child link="cingolo1"/>
    <axis xyz="0 0 0"/>
  </joint>
  <link name="supporto_ruote1">
    <!-- <inertial>
        <origin xyz="0.0526663060036786 0.166218829352237 -0.114217631298296" rpy="0 0 0" />
        <mass value="1.4914657297296" />
        <inertia ixx="0.00329358074513175" ixy="-2.17908223379448E-06" ixz="-1.37924455152832E-07" iyy="0.00284342188212464" iyz="0.000292260438790462" izz="0.00253879616079511" />
      </inertial> -->
    <visual>
      <origin rpy="0 0 0" xyz="0 0 0"/>
      <geometry>
        <mesh filename="package://tractor_description/meshes/meshes1/supporto_ruote1.STL"/>
      </geometry>
      <material name="green"/>
    </visual>
    <!-- <collision>
        <origin xyz="0 0 0" rpy="0 0 0" />
        <geometry>
          <mesh filename="package://tractor_description/meshes/meshes1/supporto_ruote1.STL" />
        </geometry>
      </collision> -->
  </link>
  <joint name="supporto_ruote1_joint" type="fixed">
    <origin rpy="-2.45232668596043 0 1.57" xyz="-0.249653977391183 -0.353238567 -0.0779139783362333"/>
    <parent link="base_link"/>
    <child link="supporto_ruote1"/>
    <axis xyz="0 0 0"/>
  </joint>
  <link name="sospensioni1">
    <!-- <inertial>
        <origin xyz="7.50000000001583E-05 0.0650296222183087 -0.202443883058338" rpy="0 0 0" />
        <mass value="0.707778785967632" />
        <inertia ixx="0.000965051218011031" ixy="-1.83010710739918E-21" ixz="1.40857955546784E-21" iyy="0.000841499560144093" iyz="0.000229345920337201" izz="0.000286941782579696" />
      </inertial> -->
    <visual>
      <origin rpy="0 0 0" xyz="0 0 0"/>
      <geometry>
        <mesh filename="package://tractor_description/meshes/meshes1/sospensioni1.STL"/>
      </geometry>
      <material name="">
        <color rgba="0.529411764705882 0.549019607843137 0.549019607843137 1"/>
      </material>
    </visual>
    <!-- <collision>
        <origin xyz="0 0 0" rpy="0 0 0" />
        <geometry>
          <mesh filename="package://tractor_description/meshes/meshes1/sospensioni1.STL" />
        </geometry>
      </collision> -->
  </link>
  <joint name="sospensioni1_joint" type="fixed">
    <origin rpy="-1.91368272087089 0 -1.5707963267949" xyz="0.115815637360445 -0.300738567 -0.0224356268106508"/>
    <parent link="base_link"/>
    <child link="sospensioni1"/>
    <axis xyz="0 0 0"/>
  </joint>
  <link name="assi1">
    <!-- <inertial>
        <origin xyz="-0.00349982980302466 0.10993552041619 -0.337199163502532" rpy="0 0 0" />
        <mass value="0.523339557828055" />
        <inertia ixx="4.94897213205783E-05" ixy="7.96456415168527E-20" ixz="-2.24741757325193E-19" iyy="0.000630937956802934" iyz="1.49820306072555E-07" izz="0.000630621119535053" />
      </inertial> -->
    <visual>
      <origin rpy="0 0 0" xyz="0 0 0"/>
      <geometry>
        <mesh filename="package://tractor_description/meshes/meshes1/assi1.STL"/>
      </geometry>
      <material name="grey"/>
    </visual>
    <!-- <collision>
        <origin xyz="0 0 0" rpy="0 0 0" />
        <geometry>
          <mesh filename="package://tractor_description/meshes/meshes1/assi1.STL" />
        </geometry>
      </collision> -->
  </link>
  <joint name="assi1_joint" type="fixed">
    <origin rpy="-1.91580745395575 0 1.57" xyz="-0.399632572527583 -0.302738567 -0.131814051628503"/>
    <parent link="base_link"/>
    <child link="assi1"/>
    <axis xyz="0 0 0"/>
  </joint>
  <link name="ruote_folli1">
    <!-- <inertial>
        <origin xyz="-0.0708297804341947 -0.25046065639353 -0.00190194641502484"  rpy="0 0 0" />
        <mass value="4.52605063451036" />
        <inertia ixx="0.011308338542401" ixy="4.33680868994202E-19" ixz="-5.04238797227858E-19" iyy="0.011308338542401" iyz="-3.45395305454324E-19" izz="0.0148674253166274" />
      </inertial> -->
    <visual>
      <origin rpy="0 0 0" xyz="0 0 0"/>
      <geometry>
        <mesh filename="package://tractor_description/meshes/meshes1/ruote_folli1.STL"/>
      </geometry>
      <material name="black"/>
    </visual>
    <!-- <collision>
        <origin xyz="0 0 0" rpy="0 0 0" />
        <geometry>
          <mesh filename="package://tractor_description/meshes/meshes1/ruote_folli1.STL" />
        </geometry>
      </collision> -->
  </link>
  <joint name="ruote_folli1_joint" type="fixed">
    <origin rpy="-1.5707963267949 -1.29575751456647 3.14" xyz="-0.399632572527583 -0.302738567 -0.131814051628503"/>
    <parent link="base_link"/>
    <child link="ruote_folli1"/>
    <axis xyz="0 0 0"/>
  </joint>
  <link name="ruota_motrice1">
    <!-- <inertial>
        <origin  xyz="5.45397060847108E-15 5.27355936696949E-16 0.0149999999999997" rpy="0 0 0" />
        <mass value="0.390201733508089" />
        <inertia ixx="0.000564504919374045" ixy="3.3881317890172E-19" ixz="-5.2103988734036E-19" iyy="0.000564504919374041" iyz="3.36362584326748E-19" izz="0.00110519879032681" />
      </inertial> -->
    <visual>
      <origin rpy="0 0 0" xyz="0 0 0"/>
      <geometry>
        <mesh filename="package://tractor_description/meshes/meshes1/ruota_motrice1.STL"/>
      </geometry>
      <material name="black"/>
    </visual>
    <!-- <collision>
        <origin xyz="0 0 0" rpy="0 0 0" />
        <geometry>
          <mesh filename="package://tractor_description/meshes/meshes1/ruota_motrice1.STL" />
        </geometry>
      </collision> -->
  </link>
  <joint name="ruota_motrice1_joint" type="fixed">
    <origin rpy="-1.5707963267949 -1.22950532384837 3.14" xyz="-0.096734450942382 -0.286388567 0.087326977068925"/>
    <parent link="base_link"/>
    <child link="ruota_motrice1"/>
    <axis xyz="0 0 0"/>
  </joint>
  <link name="ponte2">
    <!-- <inertial>
        <origin xyz="-0.0486832268427383 0.131566507147077 -0.0157825450015048" rpy="0 0 0" />
        <mass value="0.600172198642928" />
        <inertia ixx="0.00226804400768849" ixy="0.00026765453529023" ixz="6.1300083363082E-06" iyy="0.0065168708111092" iyz="4.20234806111459E-05" izz="0.00684291845907596" />
      </inertial> -->
    <visual>
      <origin rpy="0 0 0" xyz="0 0 0"/>
      <geometry>
        <mesh filename="package://tractor_description/meshes/meshes2/ponte2.STL"/>
      </geometry>
      <material name="grey"/>
    </visual>
    <!-- <collision>
        <origin xyz="0 0 0" rpy="0 0 0" />
        <geometry>
          <mesh filename="package://tractor_description/meshes/meshes2/ponte2.STL" />
        </geometry>
      </collision> -->
  </link>
  <joint name="ponte2_joint" type="fixed">
    <origin rpy="0 0 0" xyz="0 0.225 0"/>
    <parent link="base_link"/>
    <child link="ponte2"/>
    <axis xyz="0 0 0"/>
  </joint>
  <link name="cingolo2">
    <inertial>
      <origin rpy="0 0 0" xyz="-0.0186478543961228 0.0173558435086227 -8.32667268468867E-17"/>
      <mass value="5.37116770201881"/>
      <inertia ixx="0.119835058050815" ixy="0.0195379499468073" ixz="8.99361040190704E-17" iyy="0.414599681845954" iyz="3.60868166771734E-17" izz="0.519305950869416"/>
    </inertial>
    <visual>
      <origin rpy="0 0 0" xyz="0 0 0"/>
      <geometry>
        <mesh filename="package://tractor_description/meshes/meshes2/cingolo2.STL"/>
      </geometry>
      <material name="grey"/>
    </visual>
    <collision>
      <origin rpy="0 0 0" xyz="0 0 0"/>
      <geometry>
        <mesh filename="package://tractor_description/meshes/meshes2/cingolo2.STL"/>
      </geometry>
    </collision>
  </link>
  <joint name="cingolo2_joint" type="fixed">
    <origin rpy="1.57079632679489 0 3.14" xyz="-0.094340414586137 0.31585 -0.100112309063133"/>
    <parent link="base_link"/>
    <child link="cingolo2"/>
    <axis xyz="0 0 0"/>
  </joint>
  <link name="sospensioni2">
    <!-- <inertial>
        <origin xyz="7.50000000000473E-05 0.0650296222183087 -0.202443883058338" rpy="0 0 0" />
        <mass value="0.707778785967632" />
        <inertia ixx="0.000965051218011031" ixy="2.68658309636408E-19" ixz="9.89308138341378E-20" iyy="0.000841499560144093" iyz="0.0002293459203372" izz="0.000286941782579696" />
      </inertial> -->
    <visual>
      <origin rpy="0 0 0" xyz="0 0 0"/>
      <geometry>
        <mesh filename="package://tractor_description/meshes/meshes2/sospensioni2.STL"/>
      </geometry>
      <material name="">
        <color rgba="0.529411764705882 0.549019607843137 0.549019607843137 1"/>
      </material>
    </visual>
    <!-- <collision>
        <origin xyz="0 0 0" rpy="0 0 0" />
        <geometry>
          <mesh filename="package://tractor_description/meshes/meshes2/sospensioni2.STL" />
        </geometry>
      </collision> -->
  </link>
  <joint name="sospensioni2_joint" type="fixed">
    <origin rpy="-1.91368272087087 0 -1.5707963267949" xyz="0.115815637360568 0.3165 -0.022435626810643"/>
    <parent link="base_link"/>
    <child link="sospensioni2"/>
    <axis xyz="0 0 0"/>
  </joint>
  <link name="supporto_ruote2">
    <!-- <inertial>
        <origin xyz="0.0526663175440345 0.166218854266256 -0.114217636198682" rpy="0 0 0" />
        <mass value="1.49146596516459" />
        <inertia ixx="0.00329358084146592" ixy="-2.17908223062909E-06" ixz="-1.37917900814138E-07" iyy="0.00284342182877972" iyz="0.000292260692244902" izz="0.00253879632064476" />
      </inertial> -->
    <visual>
      <origin rpy="0 0 0" xyz="0 0 0"/>
      <geometry>
        <mesh filename="package://tractor_description/meshes/meshes2/supporto_ruote2.STL"/>
      </geometry>
      <material name="green"/>
    </visual>
    <!-- <collision>
        <origin xyz="0 0 0" rpy="0 0 0" />
        <geometry>
          <mesh filename="package://tractor_description/meshes/meshes2/supporto_ruote2.STL" />
        </geometry>
      </collision> -->
  </link>
  <joint name="supporto_ruote2_joint" type="fixed">
    <origin rpy="-2.45232668596046 0 1.57" xyz="-0.249653977391059 0.264 -0.0779139783362343"/>
    <parent link="base_link"/>
    <child link="supporto_ruote2"/>
    <axis xyz="0 0 0"/>
  </joint>
  <link name="assi2">
    <!-- <inertial>
        <origin xyz="-0.00349982980302445 0.200396467664505 0.0595842746769467" rpy="0 0 0" />
        <mass value="0.523339557828055" />
        <inertiaixx="4.94897213205783E-05" ixy="-9.32827811372471E-20" ixz="4.07814610477597E-18" iyy="0.000630567144483909" iyz="-4.93103460490362E-08" izz="0.000630991931854078" />
      </inertial> -->
    <visual>
      <origin rpy="0 0 0" xyz="0 0 0"/>
      <geometry>
        <mesh filename="package://tractor_description/meshes/meshes2/assi2.STL"/>
      </geometry>
      <material name="grey"/>
    </visual>
    <!-- <collision>
        <origin xyz="0 0 0" rpy="0 0 0" />
        <geometry>
          <mesh filename="package://tractor_description/meshes/meshes2/assi2.STL" />
        </geometry>
      </collision> -->
  </link>
  <joint name="assi2_joint" type="fixed">
    <origin rpy="3.06127497605204 0 1.57" xyz="-0.249653977391059 0.3145 -0.077913978336234"/>
    <parent link="base_link"/>
    <child link="assi2"/>
    <axis xyz="0 0 0"/>
  </joint>
  <link name="ruote_folli2">
    <!-- <inertial>
        <origin xyz="-0.0708297804341948 -0.232872324751677 -0.0249019464150249" rpy="0 0 0" />
        <mass value="4.52605063451035" />
        <inertia ixx="0.011308338542401" ixy="0" ixz="-2.38861526467868E-17" iyy="0.011308338542401" iyz="6.21640885808081E-18" izz="0.0148674253166274" />
      </inertial> -->
    <visual>
      <origin rpy="0 0 0" xyz="0 0 0"/>
      <geometry>
        <mesh filename="package://tractor_description/meshes/meshes2/ruote_folli2.STL"/>
      </geometry>
      <material name="black"/>
    </visual>
    <!-- <collision>
        <origin xyz="0 0 0" rpy="0 0 0" />
        <geometry>
          <mesh filename="package://tractor_description/meshes/meshes2/ruote_folli2.STL" />
        </geometry>
      </collision> -->
  </link>
  <joint name="ruote_folli2_joint" type="fixed">
    <origin rpy="-1.5707963267949 -1.29575751456645 3.14" xyz="-0.382705304353283 0.2915 -0.127037337056396"/>
    <parent link="base_link"/>
    <child link="ruote_folli2"/>
    <axis xyz="0 0 0"/>
  </joint>
  <link name="ruota_motrice2">
    <!-- <inertial>
        <origin xyz="0.26377726016691 0.128486306304607 -0.043300885340771" rpy="0 0 0" />
        <mass value="0.352270876846932" />
        <inertia ixx="0.000552782855065526" ixy="-1.57290978416372E-18" ixz="3.14137307635142E-21" iyy="0.000552782855065525" iyz="-1.8574920937579E-21" izz="0.00108208098500792" />
      </inertial> -->
    <visual>
      <origin rpy="0 0 0" xyz="0 0 0"/>
      <geometry>
        <mesh filename="package://tractor_description/meshes/meshes2/ruota_motrice2.STL"/>
      </geometry>
      <material name="black"/>
    </visual>
    <!-- <collision>
        <origin xyz="0 0 0" rpy="0 0 0" />
        <geometry>
          <mesh filename="package://tractor_description/meshes/meshes2/ruota_motrice2.STL" />
        </geometry>
      </collision> -->
  </link>
  <joint name="ruota_motrice2_joint" type="fixed">
    <origin rpy="1.5707963267949 0 0" xyz="-0.360511711109277 0.275382964 -0.041159329235658"/>
    <parent link="base_link"/>
    <child link="ruota_motrice2"/>
    <axis xyz="0 0 0"/>
  </joint>
  <!-- Control -->
  <!-- Gazebo plugin for ROS Control -->
  <gazebo reference="chassis">
    <material>Gazebo/Green</material>
  </gazebo>
  <gazebo reference="cingolo1">
    <material>Gazebo/DarkGrey</material>
  </gazebo>
  <gazebo reference="cingolo2">
    <material>Gazebo/DarkGrey</material>
  </gazebo>
  <gazebo reference="ponte1">
    <material>Gazebo/Grey</material>
  </gazebo>
  <gazebo reference="ponte2">
    <material>Gazebo/Grey</material>
  </gazebo>
  <!-- <gazebo reference="sospensioni1">
      <material>Gazebo/Black</material>
    </gazebo> -->
  <!-- <gazebo reference="sospensioni2">
      <material>Gazebo/Black</material>
    </gazebo> -->
  <gazebo reference="assi1">
    <material>Gazebo/Grey</material>
  </gazebo>
  <gazebo reference="assi2">
    <material>Gazebo/Grey</material>
  </gazebo>
  <gazebo reference="ruota_motrice1">
    <material>Gazebo/Black</material>
  </gazebo>
  <gazebo reference="ruota_motrice2">
    <material>Gazebo/Black</material>
  </gazebo>
  <gazebo reference="ruote_folli1">
    <material>Gazebo/Black</material>
  </gazebo>
  <gazebo reference="ruote_folli2">
    <material>Gazebo/Black</material>
  </gazebo>
  <gazebo reference="supporto_ruote1">
    <material>Gazebo/Green</material>
  </gazebo>
  <gazebo reference="supporto_ruote2">
    <material>Gazebo/Green</material>
  </gazebo>
  <link name="front_left_wheel">
    <!-- <visual>
            <geometry>
                <cylinder radius="${radius}" length="${length}" />
            </geometry>
        </visual> -->
    <collision>
      <geometry>
        <cylinder length="0.13" radius="0.15"/>
      </geometry>
    </collision>
    <inertial>
      <origin xyz="0 0 0"/>
      <mass value="4"/>
      <inertia ixx="0.02813333333333333" ixy="0.0" ixz="0.0" iyy="0.02813333333333333" iyz="0.0" izz="0.02813333333333333"/>
    </inertial>
  </link>
  <joint name="front_left_wheel_joint" type="continuous">
    <origin rpy=" -1.57 0 0" xyz="0.15 0.305 -0.105"/>
    <parent link="base_link"/>
    <child link="front_left_wheel"/>
    <axis xyz="0 0 1"/>
  </joint>
  <transmission name="trans_front_left_wheel">
    <type>transmission_interface/SimpleTransmission</type>
    <joint name="front_left_wheel_joint">
      <hardwareInterface>hardware_interface/VelocityJointInterface</hardwareInterface>
    </joint>
    <actuator name="motor_front_left_wheel">
      <mechanicalReduction>100</mechanicalReduction>
    </actuator>
  </transmission>
  <gazebo reference="front_left_wheel">
    <gravity>true</gravity>
    <mu1>1</mu1>
    <mu2>1</mu2>
    <kd>1</kd>
    <kp>10000000000.0</kp>
    <fdir1>0 0 1</fdir1>
    <selfCollide>false</selfCollide>
  </gazebo>
  <link name="front_right_wheel">
    <!-- <visual>
            <geometry>
                <cylinder radius="${radius}" length="${length}" />
            </geometry>
        </visual> -->
    <collision>
      <geometry>
        <cylinder length="0.13" radius="0.15"/>
      </geometry>
    </collision>
    <inertial>
      <origin xyz="0 0 0"/>
      <mass value="4"/>
      <inertia ixx="0.02813333333333333" ixy="0.0" ixz="0.0" iyy="0.02813333333333333" iyz="0.0" izz="0.02813333333333333"/>
    </inertial>
  </link>
  <joint name="front_right_wheel_joint" type="continuous">
    <origin rpy=" -1.57 0 0" xyz="0.15 -0.315 -0.105"/>
    <parent link="base_link"/>
    <child link="front_right_wheel"/>
    <axis xyz="0 0 1"/>
  </joint>
  <transmission name="trans_front_right_wheel">
    <type>transmission_interface/SimpleTransmission</type>
    <joint name="front_right_wheel_joint">
      <hardwareInterface>hardware_interface/VelocityJointInterface</hardwareInterface>
    </joint>
    <actuator name="motor_front_right_wheel">
      <mechanicalReduction>100</mechanicalReduction>
    </actuator>
  </transmission>
  <gazebo reference="front_right_wheel">
    <gravity>true</gravity>
    <mu1>1</mu1>
    <mu2>1</mu2>
    <kd>1</kd>
    <kp>10000000000.0</kp>
    <fdir1>0 0 1</fdir1>
    <selfCollide>false</selfCollide>
  </gazebo>
  <link name="rear_left_wheel">
    <!-- <visual>
            <geometry>
                <cylinder radius="${radius}" length="${length}" />
            </geometry>
        </visual> -->
    <collision>
      <geometry>
        <cylinder length="0.13" radius="0.12"/>
      </geometry>
    </collision>
    <inertial>
      <origin xyz="0 0 0"/>
      <mass value="4.23900913"/>
      <inertia ixx="0.021230370726083334" ixy="0.0" ixz="0.0" iyy="0.021230370726083334" iyz="0.0" izz="0.021230370726083334"/>
    </inertial>
  </link>
  <joint name="rear_left_wheel_joint" type="continuous">
    <origin rpy=" -1.57 0 0" xyz="-0.35 0.305 -0.132"/>
    <parent link="base_link"/>
    <child link="rear_left_wheel"/>
    <axis xyz="0 0 1"/>
  </joint>
  <transmission name="trans_rear_left_wheel">
    <type>transmission_interface/SimpleTransmission</type>
    <joint name="rear_left_wheel_joint">
      <hardwareInterface>hardware_interface/VelocityJointInterface</hardwareInterface>
    </joint>
    <actuator name="motor_rear_left_wheel">
      <mechanicalReduction>100</mechanicalReduction>
    </actuator>
  </transmission>
  <gazebo reference="rear_left_wheel">
    <gravity>true</gravity>
    <mu1>1</mu1>
    <mu2>1</mu2>
    <kd>1</kd>
    <kp>10000000000.0</kp>
    <fdir1>0 0 1</fdir1>
    <selfCollide>false</selfCollide>
  </gazebo>
  <link name="rear_right_wheel">
    <!-- <visual>
            <geometry>
                <cylinder radius="${radius}" length="${length}" />
            </geometry>
        </visual> -->
    <collision>
      <geometry>
        <cylinder length="0.13" radius="0.12"/>
      </geometry>
    </collision>
    <inertial>
      <origin xyz="0 0 0"/>
      <mass value="4.23900913"/>
      <inertia ixx="0.021230370726083334" ixy="0.0" ixz="0.0" iyy="0.021230370726083334" iyz="0.0" izz="0.021230370726083334"/>
    </inertial>
  </link>
  <joint name="rear_right_wheel_joint" type="continuous">
    <origin rpy=" -1.57 0 0" xyz="-0.35 -0.315 -0.132"/>
    <parent link="base_link"/>
    <child link="rear_right_wheel"/>
    <axis xyz="0 0 1"/>
  </joint>
  <transmission name="trans_rear_right_wheel">
    <type>transmission_interface/SimpleTransmission</type>
    <joint name="rear_right_wheel_joint">
      <hardwareInterface>hardware_interface/VelocityJointInterface</hardwareInterface>
    </joint>
    <actuator name="motor_rear_right_wheel">
      <mechanicalReduction>100</mechanicalReduction>
    </actuator>
  </transmission>
  <gazebo reference="rear_right_wheel">
    <gravity>true</gravity>
    <mu1>1</mu1>
    <mu2>1</mu2>
    <kd>1</kd>
    <kp>10000000000.0</kp>
    <fdir1>0 0 1</fdir1>
    <selfCollide>false</selfCollide>
  </gazebo>
  <gazebo reference="gps_link">
    <material>Gazebo/Blue</material>
  </gazebo>
  <link name="gps_link">
    <visual>
      <geometry>
        <box size="0.05 0.05 0.025"/>
      </geometry>
      <origin rpy="0 0 0" xyz="0 0 0"/>
      <material name="blue">
        <color rgba="0 0 1.0 1.0"/>
      </material>
    </visual>
    <collision>
      <geometry>
        <box size="0.05 0.05 0.025"/>
      </geometry>
      <origin rpy="0 0 0" xyz="0 0 0"/>
    </collision>
    <inertial>
      <origin xyz="0 0 0"/>
      <mass value="0.01"/>
      <inertia ixx="1.0" ixy="0.0" ixz="0.0" iyy="1.0" iyz="0.0" izz="1.0"/>
    </inertial>
  </link>
  <joint name="gps_joint" type="fixed">
    <parent link="base_link"/>
    <child link="gps_link"/>
    <origin rpy="0 0 0" xyz="0.05 0 0.1875"/>
    <!--        <origin rpy="0 0 0" xyz="1.05 0 3"/>-->
  </joint>
  <gazebo>
    <plugin filename="libhector_gazebo_ros_gps.so" name="gps_controller">
      <updateRate>40</updateRate>
      <robotNamespace>/</robotNamespace>
      <bodyName>gps_link</bodyName>
      <topicName>robot/fix</topicName>
      <velocityTopicName>robot/vel</velocityTopicName>
      <referenceLatitude>40.0599536</referenceLatitude>
      <referenceLongitude>18.3458069</referenceLongitude>
      <referenceHeading>0</referenceHeading>
      <referenceAltitude>0</referenceAltitude>
      <drift>0.0001 0.0001 0.0001</drift>
      <status>1</status>
      <service>1</service>
    </plugin>
  </gazebo>
  <gazebo reference="mag_link">
    <material>Gazebo/Purple</material>
  </gazebo>
  <link name="mag_link">
    <visual>
      <geometry>
        <box size="0.1 0.1 0.1"/>
      </geometry>
      <origin rpy="0 0 0" xyz="0 0 0"/>
      <material name="purple">
        <color rgba="0.611 0.317 0.73 1"/>
      </material>
    </visual>
    <collision>
      <geometry>
        <box size="0.1 0.1 0.1"/>
      </geometry>
      <origin rpy="0 0 0" xyz="0 0 0"/>
    </collision>
    <inertial>
      <origin xyz="0 0 0"/>
      <mass value="0.01"/>
      <inertia ixx="1.0" ixy="0.0" ixz="0.0" iyy="1.0" iyz="0.0" izz="1.0"/>
    </inertial>
  </link>
  <joint name="mag_joint" type="fixed">
    <parent link="base_link"/>
    <child link="mag_link"/>
    <origin rpy="0 0 0" xyz="0 0.0 0.1"/>
  </joint>
  <gazebo>
    <plugin filename="libhector_gazebo_ros_magnetic.so" name="magnetometer">
      <updateRate>40.0</updateRate>
      <bodyname>mag_link</bodyname>
      <topicName>robot/mag</topicName>
      <referenceHeading>0</referenceHeading>
      <!-- declinazione è l'angolo tra polo nord geofrafico e polo nord magnetico -->
      <declination>0.0</declination>
      <!--polo nord geografico e polo nord magnetico sono allineati -->
      <inclination>60.0</inclination>
      <offset>0 0 0</offset>
      <driftFrequency>0 0 0</driftFrequency>
      <gaussianNoise>0 0 0</gaussianNoise>
    </plugin>
  </gazebo>
  <!--
        The gazebo plugin aligns the depth data with the Z axis, with X=left and Y=up
        ROS expects the depth data along the X axis, with Y=left and Z=up
        This link only exists to give the gazebo plugin the correctly-oriented frame
      -->
  <gazebo reference="realsense">
    <material>Gazebo/White</material>
  </gazebo>
  <link name="realsense">
    <visual>
      <!--
            the model's origin is in the middle & it's rotated to lie in
            the optical standard with X left, Y up, and Z forward
            -->
      <origin rpy="1.570796 0 1.570796" xyz="0.0115 0 0.0100"/>
      <geometry>
        <!-- Origin of this mesh is the base of the bracket. -->
        <mesh filename="package://realsense2_description/meshes/d435.dae"/>
      </geometry>
      <material name="white">
        <color rgba="1 1 1.0 1.0"/>
      </material>
    </visual>
    <collision>
      <geometry>
        <!-- Origin of this mesh is the base of the bracket. -->
        <mesh filename="package://realsense2_description/meshes/d435.dae"/>
      </geometry>
      <origin rpy="1.570796 0 1.570796" xyz="0.0115 0 0.0100"/>
    </collision>
  </link>
  <joint name="realsense_joint" type="fixed">
    <parent link="base_link"/>
    <child link="realsense"/>
    <origin rpy="0 0 1.57" xyz="0.1 0.0 0.5"/>
  </joint>
  <gazebo reference="realsense">
    <turnGravityOff>true</turnGravityOff>
    <sensor name="realsense_depth" type="depth">
      <update_rate>30</update_rate>
      <camera>
        <!-- 75x65 degree FOV for the depth sensor -->
        <horizontal_fov>1.5184351666666667</horizontal_fov>
        <vertical_fov>1.0122901111111111</vertical_fov>
        <image>
          <width>640</width>
          <height>480</height>
          <!-- TODO: check what format the Realsense hardware delivers and set this to match! -->
          <format>RGB_INT8</format>
        </image>
        <clip>
          <!-- give the color sensor a maximum range of 50m so that the simulation renders nicely -->
          <near>0.01</near>
          <far>50.0</far>
        </clip>
      </camera>
      <plugin filename="libgazebo_ros_openni_kinect.so" name="kinect_controller">
        <baseline>0.2</baseline>
        <alwaysOn>true</alwaysOn>
        <updateRate>30</updateRate>
        <cameraName>robot/camera</cameraName>
        <imageTopicName>color/image_raw</imageTopicName>
        <cameraInfoTopicName>color/camera_info</cameraInfoTopicName>
        <depthImageTopicName>depth/image_rect_raw</depthImageTopicName>
        <depthImageInfoTopicName>depth/camera_info</depthImageInfoTopicName>
        <pointCloudTopicName>depth/color/points</pointCloudTopicName>
        <frameName>realsense</frameName>
        <pointCloudCutoff>0.105</pointCloudCutoff>
        <pointCloudCutoffMax>8.0</pointCloudCutoffMax>
        <distortionK1>0.00000001</distortionK1>
        <distortionK2>0.00000001</distortionK2>
        <distortionK3>0.00000001</distortionK3>
        <distortionT1>0.00000001</distortionT1>
        <distortionT2>0.00000001</distortionT2>
        <CxPrime>0</CxPrime>
        <Cx>0</Cx>
        <Cy>0</Cy>
        <focalLength>0</focalLength>
        <hackBaseline>0</hackBaseline>
      </plugin>
    </sensor>
  </gazebo>
  <link name="velodyne_vlp16_base_link">
    <inertial>
      <mass value="0.83"/>
      <origin xyz="0 0 0.03585"/>
      <inertia ixx="0.000908059425" ixy="0" ixz="0" iyy="0.000908059425" iyz="0" izz="0.0011049624"/>
    </inertial>
    <visual>
      <geometry>
        <mesh filename="package://velodyne_description/meshes/VLP16_base_1.dae"/>
      </geometry>
    </visual>
    <visual>
      <geometry>
        <mesh filename="package://velodyne_description/meshes/VLP16_base_2.dae"/>
      </geometry>
    </visual>
    <collision>
      <origin rpy="0 0 0" xyz="0 0 0.03585"/>
      <geometry>
        <cylinder length="0.0717" radius="0.0516"/>
      </geometry>
    </collision>
  </link>
  <joint name="velodyne_vlp16_base_joint" type="fixed">
    <origin rpy="0 0 0" xyz="-0.03 0 0.2"/>
    <parent link="base_link"/>
    <child link="velodyne_vlp16_base_link"/>
  </joint>
  <link name="velodyne_vlp16">
    <inertial>
      <mass value="0.01"/>
      <origin xyz="0 0 0"/>
      <inertia ixx="1e-7" ixy="0" ixz="0" iyy="1e-7" iyz="0" izz="1e-7"/>
    </inertial>
    <visual>
      <origin xyz="0 0 -0.0377"/>
      <geometry>
        <mesh filename="package://velodyne_description/meshes/VLP16_scan.dae"/>
      </geometry>
    </visual>
  </link>
  <joint name="velodyne_vlp16_joint" type="fixed">
    <origin rpy="0 0 0" xyz="0 0 0.0377"/>
    <parent link="velodyne_vlp16_base_link"/>
    <child link="velodyne_vlp16"/>
  </joint>
  <gazebo reference="velodyne_vlp16">
    <sensor name="VLP16" type="gpu_ray">
      <pose>0 0 0 0 0 0</pose>
      <visualize>false</visualize>
      <update_rate>10</update_rate>
      <ray>
        <scan>
          <horizontal>
            <samples>360</samples>
            <resolution>1</resolution>
            <min_angle>-3.141592653589793</min_angle>
            <max_angle>3.141592653589793</max_angle>
          </horizontal>
          <vertical>
            <samples>16</samples>
            <resolution>1</resolution>
            <min_angle>-0.2617993877991494</min_angle>
            <max_angle> 0.2617993877991494</max_angle>
          </vertical>
        </scan>
        <range>
          <min>1</min>
          <max>140</max>
          <resolution>0.001</resolution>
        </range>
        <noise>
          <type>gaussian</type>
          <mean>0.0</mean>
          <stddev>0.0</stddev>
        </noise>
      </ray>
      <plugin filename="libgazebo_ros_velodyne_gpu_laser.so" name="gazebo_ros_laser_controller">
        <topicName>robot/velodyne</topicName>
        <frameName>velodyne_vlp16</frameName>
        <min_range>1</min_range>
        <max_range>140</max_range>
        <gaussianNoise>0.008</gaussianNoise>
      </plugin>
    </sensor>
  </gazebo>
  <link name="base_link">
    <inertial>
      <origin xyz="0.0 0.0 0.0"/>
      <mass value="15"/>
      <inertia ixx="0.001" ixy="0.0" ixz="0.0" iyy="0.001" iyz="0.0" izz="0.001"/>
    </inertial>
    <visual>
      <origin rpy="0 0 0" xyz="0 0.0 0.0"/>
      <geometry>
        <box size="0.1 0.1 0.1"/>
      </geometry>
    </visual>
    <collision>
      <origin rpy="0 0 0" xyz="0 0.0 0.0 "/>
      <geometry>
        <box size="0.1 0.1 0.1"/>
      </geometry>
    </collision>
  </link>
</robot>
