<?xml version="1.0"?>


<robot xmlns:xacro="http://ros.org/wiki/xacro" name="jumpleg">

    <!-- Things that are needed only for Gazebo (not the physical robot). These include sensor and controller plugin specifications -->
    <xacro:include filename="$(find jumpleg_description)/urdf/leg.transmission.xacro"/>
    <xacro:include filename="$(find jumpleg_description)/urdf/leg.gazebo.xacro"/>


    <!-- These are absoulte distance value, the sign are decided below -->
    <xacro:property name="base_2_HAA_x" value="0" />
    <xacro:property name="base_2_HAA_y" value="0" />

    <xacro:property name="HAA_2_HFE_y" value="${14.0 * 0.001}" />

    <xacro:property name="base_2_HFE_x" value="${190.00 * 0.001}" />
    <xacro:property name="base_2_HFE_y" value="${104.60 * 0.001}" />

    <xacro:property name="HFE_2_KFE_y" value="${37.45 * 0.001}" />
    <xacro:property name="HFE_2_KFE_z" value="${160.00 * 0.001}" />

    <xacro:property name="KFE_2_FOOT_y" value="${8.0 * 0.001}" />
    <xacro:property name="KFE_2_FOOT_z" value="${160.00 * 0.001}" />
    

    <!-- This macro has for purpose to define a leg -->
    <xacro:macro name="leg" params="prefix is_front is_right has_side_motion
                                  color_name color opacity">
    

        <xacro:if value="${has_side_motion}">
            <!--HAA JOINT: Joint between the trunk and the hip assembly -->
            <joint name="${prefix}_haa_joint" type="revolute">
                <parent link="trunk"/>
                <child link="${prefix}_hip_assembly"/>
                <!-- joints rotates around the x-axis -->
                <axis xyz="1 0 0"/>


                <!-- limit and placement of the joint -->
                
                <xacro:if value="${is_front}">
                    <xacro:unless value="${is_right}">
                        <!-- LF_HAA_JOINT -->
                        <!-- lower=-75deg, upper=140, velocity=555.5rpm (=5000rpm motor-side) -->
                        <limit effort="${MAX_TORQUE}" lower="${haa_min}" upper="${haa_max}" velocity="58.17764173"/>
			<safety_controller k_position="10" k_velocity="1"   soft_lower_limit="${haa_min_soft}" soft_upper_limit="${haa_max_soft}" />
                        <origin xyz="${base_2_HAA_x} ${base_2_HAA_y} 0" rpy="0 0 0" />
                    </xacro:unless>
                    <xacro:if value="${is_right}">
                        <!-- RF_HAA_JOINT -->
                        <!-- lower=-140deg, upper=75, velocity=555.5rpm (=5000rpm motor-side) -->
                        <limit effort="${MAX_TORQUE}" lower="-${haa_max}" upper="-${haa_min}" velocity="58.17764173"/>
			<safety_controller k_position="10" k_velocity="1"   soft_lower_limit="-${haa_max_soft}" soft_upper_limit="-${haa_min_soft}" />
                        <origin xyz="${base_2_HAA_x} ${-base_2_HAA_y} 0" rpy="0 0 0" />
                    </xacro:if>
                </xacro:if>
                <xacro:unless value="${is_front}">
                    <xacro:unless value="${is_right}">
                        <!-- LH_HAA_JOINT -->
                        <!-- lower=-75deg, upper=140, velocity=555.5rpm (=5000rpm motor-side) -->
                        <limit effort="${MAX_TORQUE}" lower="${haa_min}" upper="${haa_max}" velocity="58.17764173"/>
			<safety_controller k_position="10" k_velocity="1"   soft_lower_limit="${haa_min_soft}" soft_upper_limit="${haa_max_soft}" />
                        <origin xyz="${-base_2_HAA_x} ${base_2_HAA_y} 0" rpy="0 0 0" />
                    </xacro:unless>
                    <xacro:if value="${is_right}">
                        <!-- RH_HAA_JOINT -->
                        <!-- lower=-140deg, upper=75, velocity=555.5rpm (=5000rpm motor-side) -->
                        <limit effort="${MAX_TORQUE}" lower="-${haa_max}" upper="-${haa_min}" velocity="58.17764173"/>
			<safety_controller k_position="10" k_velocity="1"   soft_lower_limit="-${haa_max_soft}" soft_upper_limit="-${haa_min_soft}" />
                        <origin xyz="${-base_2_HAA_x} ${-base_2_HAA_y} 0" rpy="0 0 0" />

                    </xacro:if>
                </xacro:unless>
                
                <!-- pybullet simulation parameters -->
                <dynamics damping="0.0" friction="0.0"/>
            </joint>


            <!-- HIP ASSEMBLY -->	
            <link name="${prefix}_hip_assembly">
            	<!-- create a dummy hip_assembly link to join the two joints -->
            	<!-- HIP ASSEMBLY VISUAL-->	
	            <visual>
                    <xacro:if value="${is_front}">
                        <xacro:unless value="${is_right}">
                            <!-- LF HIP ASSEMBLY -->
                            <origin xyz="0.01950 0 0" rpy="0 0 0" />
                        	<geometry>
                        	    <mesh filename="package://jumpleg_description/meshes/stl/solo12/solo12_hip_fe_fl.stl"/>
                        	</geometry>
                        </xacro:unless>
                        <xacro:if value="${is_right}">
                            <!-- RF HIP ASSEMBLY -->
                            <origin xyz="0.01950 0 0" rpy="0 0 0" />
                        	<geometry>
                        	    <mesh filename="package://jumpleg_description/meshes/stl/solo12/solo12_hip_fe_fr.stl"/>
                        	</geometry>
                        </xacro:if>
                    </xacro:if>
                    <xacro:unless value="${is_front}">
                        <xacro:unless value="${is_right}">
                            <!-- LH HIP ASSEMBLY -->
                            <origin xyz="-0.01950 0 0" rpy="0 0 0" />
                        	<geometry>
                        	    <mesh filename="package://jumpleg_description/meshes/stl/solo12/solo12_hip_fe_hl.stl"/>
                        	</geometry>
                        </xacro:unless>
                        <xacro:if value="${is_right}">
                            <!-- RH HIP ASSEMBLY -->
                            <origin xyz="-0.01950 0 0" rpy="0 0 0" />
                        	<geometry>
                        	    <mesh filename="package://jumpleg_description/meshes/stl/solo12/solo12_hip_fe_hr.stl"/>
                        	</geometry>
                        </xacro:if>
                    </xacro:unless>
	                <material name="${color_name}">
                    	<color rgba="${color} ${opacity}"/>
                	</material>
	            </visual>
	            
	            <!-- HIP ASSEMBLY COLLISION-->	
	            <collision>
                    <xacro:if value="${is_front}">
                        <xacro:unless value="${is_right}">
                            <!-- LF HIP ASSEMBLY -->
                            <origin xyz="0.01950 0 0" rpy="0 0 0" />
                        	<geometry>
                        	    <mesh filename="package://jumpleg_description/meshes/stl/solo12/solo12_hip_fe_fl.stl"/>
                        	</geometry>
                        </xacro:unless>
                        <xacro:if value="${is_right}">
                            <!-- RF HIP ASSEMBLY -->
                            <origin xyz="0.01950 0 0" rpy="0 0 0" />
                        	<geometry>
                        	    <mesh filename="package://jumpleg_description/meshes/stl/solo12/solo12_hip_fe_fr.stl"/>
                        	</geometry>
                        </xacro:if>
                    </xacro:if>
                    <xacro:unless value="${is_front}">
                        <xacro:unless value="${is_right}">
                            <!-- LH HIP ASSEMBLY -->
                            <origin xyz="-0.01950 0 0" rpy="0 0 0" />
                        	<geometry>
                        	    <mesh filename="package://jumpleg_description/meshes/stl/solo12/solo12_hip_fe_hl.stl"/>
                        	</geometry>
                        </xacro:unless>
                        <xacro:if value="${is_right}">
                            <!-- RH HIP ASSEMBLY -->
                            <origin xyz="-0.01950 0 0" rpy="0 0 0" />
                        	<geometry>
                        	    <mesh filename="package://jumpleg_description/meshes/stl/solo12/solo12_hip_fe_hr.stl"/>
                        	</geometry>
                        </xacro:if>
                    </xacro:unless>
	                <material name="${color_name}">
                    	<color rgba="${color} ${opacity}"/>xacro
                	</material>
	            </collision>
	    
	            <!-- HIP ASSEMBLY INERTIAL -->
	            <inertial>
	                <mass value="0.14853845"/>
	                
	                <xacro:if value="${is_front}">
                        <xacro:unless value="${is_right}">
                            <!-- LF HIP ASSEMBLY -->
                            <origin xyz="-0.07870700 0.01 0." rpy="0 0 0" />
	                        <inertia ixx="0.00003024" ixy="0.00004671" ixz="0.0"
		                                              iyy="0.00041193" iyz="0.0"
		                                                               izz="0.00041107"/>
                        </xacro:unless>
                        <xacro:if value="${is_right}">
                            <!-- RF HIP ASSEMBLY -->
                            <origin xyz="-0.07870700 -0.01 0." rpy="0 0 0" />
                            <inertia ixx="0.00003024" ixy="-0.00004671" ixz="0.0"
		                                              iyy="0.00041193"  iyz="0.0"
		                                                                izz="0.00041107"/>  
                        </xacro:if>
                    </xacro:if>
                    <xacro:unless value="${is_front}">
                        <xacro:unless value="${is_right}">
                            <!-- LH HIP ASSEMBLY -->
                            <origin xyz="0.07870700 0.01 0." rpy="0 0 0" />
	                        <inertia ixx="0.00003024" ixy="0.00004671" ixz="0.0"
	                                                  iyy="0.00041193" iyz="0.0"
		                                                               izz="0.00041107"/>
                        </xacro:unless>
                        <xacro:if value="${is_right}">
                            <!-- RH HIP ASSEMBLY -->
                            <origin xyz="0.07870700 -0.01 0." rpy="0 0 0" />
                            <inertia ixx="0.00003024" ixy="-0.00004671" ixz="0.0"
		                                              iyy="0.00041193"  iyz="0.0"
		                                                                izz="0.00041107"/>
                        </xacro:if>
                    </xacro:unless>           
	            </inertial>
	        </link>        
                        
            <!--HFE JOINT-->
            <joint name="${prefix}_hfe_joint" type="revolute">
                <parent link="${prefix}_hip_assembly"/>
                <child link="${prefix}_upper_leg"/>
                <!-- joints rotates around the y-axis -->
                <axis xyz="0 1 0"/>
                <!-- limit and placement of the joint -->
                <xacro:if value="${is_front}">
                    <xacro:unless value="${is_right}">
                        <!-- LF_HFE_JOINT -->
                        <!-- lower=-225deg, upper=90deg, velocity=555.5rpm (=5000rpm motor-side) -->
                        <limit effort="${MAX_TORQUE}" lower="${hfe_min}" upper="${hfe_max}" velocity="58.17764173"/>
			<safety_controller k_position="10" k_velocity="1"   soft_lower_limit="${hfe_min_soft}" soft_upper_limit="${hfe_max_soft}" />                 
                        <origin xyz="0 ${HAA_2_HFE_y} 0" rpy="0 0 0" />
                    </xacro:unless>
                    <xacro:if value="${is_right}">
                        <!-- RF_HFE_JOINT -->
                        <!-- lower=-225deg, upper=90deg, velocity=555.5rpm (=5000rpm motor-side) -->
                        <limit effort="${MAX_TORQUE}" lower="${hfe_min}" upper="${hfe_max}" velocity="58.17764173"/>
			<safety_controller k_position="10" k_velocity="1"   soft_lower_limit="${hfe_min_soft}" soft_upper_limit="${hfe_max_soft}" />
                        <origin xyz="0 ${-HAA_2_HFE_y} 0" rpy="0 0 0" />
                    </xacro:if>
                </xacro:if>
                <xacro:unless value="${is_front}">
                    <xacro:unless value="${is_right}">
                        <!-- LH_HFE_JOINT -->
                        <!-- lower=-90deg, upper=225deg, velocity=555.5rpm (=5000rpm motor-side) -->
                        <limit effort="${MAX_TORQUE}" lower="-${hfe_max}" upper="-${hfe_min}" velocity="58.17764173"/>
			<safety_controller k_position="10" k_velocity="1"   soft_lower_limit="-${hfe_max_soft}" soft_upper_limit="-${hfe_min_soft}" />
                        <origin xyz="0 ${HAA_2_HFE_y} 0" rpy="0 0 0" />
                    </xacro:unless>
                    <xacro:if value="${is_right}">
                        <!-- RF_HFE_JOINT -->
                        <!-- lower=-90deg, upper=225deg, velocity=555.5rpm (=5000rpm motor-side) -->
                        <limit effort="${MAX_TORQUE}" lower="-${hfe_max}" upper="-${hfe_min}" velocity="58.17764173"/>
			<safety_controller k_position="10" k_velocity="1"   soft_lower_limit="-${hfe_max_soft}" soft_upper_limit="-${hfe_min_soft}" />
                        <origin xyz="0 ${-HAA_2_HFE_y} 0" rpy="0 0 0" />
                    </xacro:if>
                </xacro:unless>
                
                
                
                <!-- pybullet simulation parameters -->
                <dynamics damping="0.0" friction="0.0"/>
            </joint>
        </xacro:if>
        
        <!-- SOLO 9 -->
        <xacro:unless value="${has_side_motion}">
            <!-- Joint between the base and the ${prefix} upper leg -->
            <joint name="${prefix}_hfe_joint" type="revolute">
                <parent link="trunk"/>
                <child link="${prefix}_upper_leg"/>
                <limit effort="1000" lower="-10" upper="10" velocity="1000"/>
                <!-- joints rotates around the y-axis -->
                <axis xyz="0 1 0"/>
                <!-- placement of the joint -->
                <xacro:if value="${is_front}">
                    <xacro:unless value="${is_right}">
                        <origin xyz="${base_2_HFE_x} ${base_2_HFE_y} 0" rpy="0 0 0" />
                    </xacro:unless>
                    <xacro:if value="${is_right}">
                        <origin xyz="${base_2_HFE_x} ${-base_2_HFE_y} 0" rpy="0 0 0" />
                    </xacro:if>
                </xacro:if>
                <xacro:unless value="${is_front}">
                    <xacro:unless value="${is_right}">
                        <origin xyz="${-base_2_HFE_x} ${base_2_HFE_y} 0" rpy="0 0 0" />
                    </xacro:unless>
                    <xacro:if value="${is_right}">
                        <origin xyz="${-base_2_HFE_x} ${-base_2_HFE_y} 0" rpy="0 0 0" />
                    </xacro:if>
                </xacro:unless>
                <!-- pybullet simulation parameters -->
                <dynamics damping="0.0" friction="0.0"/>
            </joint>
        </xacro:unless>


        <!-- UPPER LEG LINK -->
        <link name="${prefix}_upper_leg">
            <!-- UPPER LEG LINK INERTIAL -->
            <xacro:unless value="${is_right}">
                <!-- Left upper leg inertia -->
                <inertial>
                    <origin xyz="0.00001377 0.01935853 -0.07870700" rpy="0 0 0" />
                    <mass value="0.14853845"/>
                    <inertia ixx="0.00041107" ixy="0.0"         ixz="0.0"
                                              iyy="0.00041193"  iyz="0.00004671"
                                                                izz="0.00003024"/>
                </inertial>
            </xacro:unless>
            <xacro:if value="${is_right}">
            <!-- Right upper leg inertia -->
                <inertial>
                    <origin xyz="-0.00001377 -0.01935853 -0.07870700" rpy="0 0 0" />
                    <mass value="0.14853845"/>
                    <inertia ixx="0.00041107" ixy="0.0"         ixz="0.0"
                                              iyy="0.00041193"  iyz="-0.00004671"
                                                                izz="0.00003024"/>
                </inertial>
            </xacro:if>
            
            <!-- UPPER LEG LINK VISUAL -->
            <visual>
                <origin xyz="0 0 0" rpy="0 0 0" />
                <geometry>
                    <xacro:unless value="${is_right}">
                        <mesh filename="package://jumpleg_description/meshes/stl/with_foot/solo_upper_leg_left_side.stl"/>
                    </xacro:unless>
                    <xacro:if value="${is_right}">
                        <mesh filename="package://jumpleg_description/meshes/stl/with_foot/solo_upper_leg_right_side.stl"/>
                    </xacro:if>
                </geometry>
                <material name="${color_name}">
                    <color rgba="${color} ${opacity}"/>
                </material>
            </visual>
            
            <!-- UPPER LEG LINK COLLISION -->
            <collision>
                <origin xyz="0 0 0" rpy="0 0 0" />
                <geometry>
                    <xacro:unless value="${is_right}">
                        <mesh filename="package://jumpleg_description/meshes/stl/with_foot/solo_upper_leg_left_side.stl"/>
                    </xacro:unless>
                    <xacro:if value="${is_right}">
                        <mesh filename="package://jumpleg_description/meshes/stl/with_foot/solo_upper_leg_right_side.stl"/>
                    </xacro:if>
                </geometry>
                <material name="${color_name}">
                    <color rgba="${color} ${opacity}"/>
                </material>
            </collision>
            <!-- Bullet specific paramters -->
            <contact>
                <lateral_friction value="1.0"/>
                <restitution value="0.5"/>
            </contact>
        </link> <!-- END UPPER LEG LINK -->




        <!-- KFE JOINT: Joint between the upper leg and the lower leg -->
        <joint name="${prefix}_kfe_joint" type="revolute">
            <parent link="${prefix}_upper_leg"/>
            <child link="${prefix}_lower_leg"/>
            <!-- joints rotates around the y-axis -->
            <axis xyz="0 1 0"/>
            <!-- limit and placement of the joint -->
            <xacro:if value="${is_front}">
                <xacro:unless value="${is_right}">
                    <!-- LF_KFE JOINT -->
                    <!-- lower=-370deg, upper=370deg, velocity=555.5rpm (=5000rpm motor-side) -->
                    <limit effort="${MAX_TORQUE}" lower="${kfe_min}" upper="${kfe_max}" velocity="58.17764173"/>
		    <safety_controller k_position="10" k_velocity="1"   soft_lower_limit="${kfe_min}" soft_upper_limit="${kfe_max}" />
                    <origin xyz="0 ${HFE_2_KFE_y} ${-HFE_2_KFE_z}" rpy="0 0 0" />
                </xacro:unless>
                <xacro:if value="${is_right}">
                    <!-- RF_KFE JOINT -->
                    <!-- lower=-370deg, upper=370deg, velocity=555.5rpm (=5000rpm motor-side) -->
                    <limit effort="${MAX_TORQUE}" lower="${kfe_min}" upper="${kfe_max}" velocity="58.17764173"/>
		    <safety_controller k_position="10" k_velocity="1"   soft_lower_limit="${kfe_min}" soft_upper_limit="${kfe_max}" />
                    <origin xyz="0 ${-HFE_2_KFE_y} ${-HFE_2_KFE_z}" rpy="0 0 0" />
                </xacro:if>
            </xacro:if>
            <xacro:unless value="${is_front}">
                <xacro:unless value="${is_right}">
                    <!-- LH_KFE JOINT -->
                    <!-- lower=-370deg, upper=370deg, velocity=555.5rpm (=5000rpm motor-side) -->
                    <limit effort="${MAX_TORQUE}" lower="${kfe_min}" upper="${kfe_max}" velocity="58.17764173"/>
		    <safety_controller k_position="10" k_velocity="1"   soft_lower_limit="${kfe_min}" soft_upper_limit="${kfe_max}" />
                    <origin xyz="0 ${HFE_2_KFE_y} ${-HFE_2_KFE_z}" rpy="0 0 0" />
                </xacro:unless>
                <xacro:if value="${is_right}">
                    <!-- RH_KFE JOINT -->
                    <!-- lower=-370deg, upper=370deg, velocity=555.5rpm (=5000rpm motor-side) -->
                    <limit effort="${MAX_TORQUE}" lower="${kfe_min}" upper="${kfe_max}" velocity="58.17764173"/>
		    <safety_controller k_position="10" k_velocity="1"   soft_lower_limit="${kfe_min}" soft_upper_limit="${kfe_max}" />
                    <origin xyz="0 ${-HFE_2_KFE_y} ${-HFE_2_KFE_z}" rpy="0 0 0" />
                </xacro:if>
            </xacro:unless>
            <!-- pybullet simulation parameters -->
            <dynamics damping="0.0" friction="0.0"/>
        </joint>



        <!-- LOWERLEG -->
        <link name="${prefix}_lower_leg">
            <!-- LOWER LEG LINK INERTIAL -->
            <xacro:unless value="${is_right}">
                <!-- Left lower leg inertia -->
                <inertial>
                <origin xyz="0.0 0.00787644 -0.08928215" rpy="0 0 0" />
                <mass value="0.03070001"/>
                <inertia ixx="0.00012024" ixy="0.0"         ixz="0.0"
                                          iyy="0.00012029"  iyz="0.00000305"
                                                            izz="0.00000216"/>
                </inertial>
            </xacro:unless>
            <xacro:if value="${is_right}">
                <!-- Right lower leg inertia -->
                <inertial>
                <origin xyz="0.0 0.00787644 -0.08928215" rpy="0 0 0" />
                <mass value="0.03070001"/>
                <inertia ixx="0.00012024" ixy="0.0"         ixz="0.0"
                                          iyy="0.00012029"  iyz="-0.00000305"
                                                            izz="0.00000216"/>
                </inertial>
            </xacro:if>
           
            <!-- LOWER LEG LINK VISUAL -->
            <visual>
                <origin xyz="0 0 0" rpy="0 0 0" />
                <geometry>
                    <xacro:unless value="${is_right}">
                        <mesh filename="package://jumpleg_description/meshes/stl/with_foot/solo_lower_leg_left_side.stl"/>
                    </xacro:unless>
                    <xacro:if value="${is_right}">
                        <mesh filename="package://jumpleg_description/meshes/stl/with_foot/solo_lower_leg_right_side.stl"/>
                    </xacro:if>
                </geometry>
                <material name="${color_name}">
                    <color rgba="${color} ${opacity}"/>
                </material>
            </visual>
            
            <!-- LOWER LEG LINK COLLISION -->
            <collision>
                <origin xyz="0 0 0" rpy="0 0 0" />
                <geometry>
                    <xacro:unless value="${is_right}">
                        <mesh filename="package://jumpleg_description/meshes/stl/with_foot/solo_lower_leg_left_side.stl"/>
                    </xacro:unless>
                    <xacro:if value="${is_right}">
                        <mesh filename="package://jumpleg_description/meshes/stl/with_foot/solo_lower_leg_right_side.stl"/>
                    </xacro:if>
                </geometry>
                <material name="${color_name}">
                    <color rgba="${color} ${opacity}"/>
                </material>
            </collision>
            <!-- Bullet specific paramters -->
            <contact>
                <lateral_friction value="1.0"/>
                <restitution value="0.5"/>
            </contact>
        </link> <!-- END LOWER LEG LINK -->


        <!-- ANKLE: (Fixed) joint between the lower leg and the foot -->
        <joint name="${prefix}_ankle" type="fixed">
            <parent link="${prefix}_lower_leg"/>
            <child link="${prefix}_foot"/>
            <!-- Joint placement --> 
            <xacro:unless value="${is_right}">
                <origin xyz="0 ${KFE_2_FOOT_y} ${-KFE_2_FOOT_z}" rpy="0 0 0" />
            </xacro:unless>
            
            <xacro:if value="${is_right}">
                <origin xyz="0 ${-KFE_2_FOOT_y} ${-KFE_2_FOOT_z}" rpy="0 0 0" />
            </xacro:if>

            <!-- pybullet simulation parameters -->
            <dynamics damping="0.0" friction="0.0"/>
        </joint>


        <!-- FOOT -->
        <link name="${prefix}_foot">
            <!-- FOOT INERTIAL -->
            <!-- This link is symmetrical left or right -->
            <inertial>
                <origin xyz="0 0 0.00035767" rpy="0 0 0" />
                <mass value="0.00693606"/>
                <inertia ixx="0.00000057" ixy="0.0"         ixz="0.0"
                                          iyy="0.00000084"  iyz="0.0"
                                                            izz="0.00000053"/>
            </inertial>
            
            <!-- FOOT VISUAL -->
            <visual>
                <origin xyz="0 0 0" rpy="0 0 0" />
                <geometry>
                    <mesh filename="package://jumpleg_description/meshes/stl/with_foot/solo_foot.stl"/>
                </geometry>
                <material name="${color_name}">
                    <color rgba="${color} ${opacity}"/>
                </material>
            </visual>
            
            <!-- FOOT COLLISION -->
            <collision>
                <origin xyz="0 0 0" rpy="0 0 0" />
                <geometry>
                    <mesh filename="package://jumpleg_description/meshes/stl/with_foot/solo_foot.stl"/>
                    <!-- sphere radius="0.01"/-->
                </geometry>
                <material name="${color_name}">
                    <color rgba="${color} ${opacity}"/>
                </material>
            </collision>
            
            <!-- Bullet specific paramters -->
            <contact>
                <lateral_friction value="1.0"/>
                <restitution value="0.5"/>
            </contact>
        </link> <!-- END FOOT LINK -->

        <!-- Extensions -->
        <xacro:leg_transmission name="${prefix}"/>
        <xacro:leg_gazebo name="${prefix}"/>
    </xacro:macro>
</robot>
